Workbook

Sheet Truncated data
A1: {=Sheet5!A1:S10} -> 0 | B1: αβ_combination | C1: MW | D1: RT | E1: ACPC | F1: charge | G1: ab ratio | H1: MIC_CA | I1: MIC_CT | J1: MIC_CP | K1: MIC_CG | L1: MIC_SA | M1: MIC_EC | N1: IC50_HUVEC | O1: IC50_3T3 | P1: HC10 | Q1: Helicity | R1: ME100 | S1: ME15
A2: #001 | B2: α | C2: 1479.787 | D2: 22.89 | E2: 0 | F2: 1 | G2: 0 | H2: 6 | I2: 5.6666667 | J2: 6.6666667 | K2: 7.6666667 | L2: 5.6666667 | M2: 4.6666667 | N2: 6.0145556 | O2: 5.8101554 | P2: 5.129283 | Q2: 83.5 | R2: -23.4 | S2: -19.5
A3: #012 | B3: ααβ | C3: 1481.939 | D3: 16.28 | E3: 2 | F3: 5 | G3: 33.33 | H3: 4.6666667 | I3: 4 | J3: 4.6666667 | K3: 6.6666667 | L3: 3.6666667 | M3: 2.6666667 | N3: 6.9285302 | O3: 6.8948252 | P3: 7.7279205 | Q3: 55.7 | R3: -57.1 | S3: -31.8
A4: #013 | B4: ααβ | C4: 1524.02 | D4: 18.37 | E4: 2 | F4: 5 | G4: 33.33 | H4: 3 | I4: 2.6666667 | J4: 3.6666667 | K4: 5.6666667 | L4: 2 | M4: 2.3333333 | N4: 4.6641934 | O4: 4.6644793 | P4: 5.3680699 | Q4: 67.5 | R4: -58.8 | S4: -39.7
A5: #014 | B5: ααβ | C5: 1550.102 | D5: 19.45 | E5: 2 | F5: 5 | G5: 33.33 | H5: 2.3333333 | I5: 3 | J5: 3 | K5: 4.6666667 | L5: 2 | M5: 4.6666667 | N5: 2.9945497 | O5: 3.2390771 | P5: 1.8073549 | Q5: 88 | R5: -44.6 | S5: -39.3
A6: #029 | B6: ααβαααβ | C6: 1515.956 | D6: 17.18 | E6: 2 | F6: 5 | G6: 28.57 | H6: 4 | I6: 3.3333333 | J6: 3.6666667 | K6: 6 | L6: 3.3333333 | M6: 2.6666667 | N6: 6.5674964 | O6: 6.0126818 | P6: 7.243174 | Q6: 51.7 | R6: -53.7 | S6: -27.7
A7: #029-G1K-p6 | B7: ααβαααβ | C7: 1587.079 | D7: 15.13 | E7: 2 | F7: 6 | G7: 28.57 | H7: 4.6666667 | I7: 4 | J7: 4 | K7: 6.6666667 | L7: 3.3333333 | M7: 3 | N7: 6.9333809 | O7: 5.9820907 | P7: 7.8054214 | Q7: 46.9 | R7: -41.8 | S7: -19.6
A8: #032 | B8: ααβαααβ | C8: 1516.896 | D8: 19.17 | E8: 2 | F8: 3 | G8: 28.57 | H8: 5 | I8: 5 | J8: 5.3333333 | K8: 6.6666667 | L8: 4 | M8: 3 | N8: 6.6773725 | O8: 6.6707269 | P8: 7.1618877 | Q8: 70.7 | R8: -54.2 | S8: -38.3
A9: #035 | B9: ααβαααβ | C9: 1502.869 | D9: 19.67 | E9: 2 | F9: 3 | G9: 28.57 | H9: 4 | I9: 3.6666667 | J9: 4.3333333 | K9: 6.3333333 | L9: 3 | M9: 2.3333333 | N9: 5.7036429 | O9: 5.4373957 | P9: 5.5484366 | Q9: 73.1 | R9: -54.7 | S9: -40
A10: #038 | B10: ααβαααβ | C10: 1548.042 | D10: 16.97 | E10: 0 | F10: 5 | G10: 28.57 | H10: 4 | I10: 4.6666667 | J10: 4.6666667 | K10: 6.3333333 | L10: 2.5 | M10: 4 | N10: 5.6765852 | O10: 4.7248704 | P10: 5.9886847 | Q10: 25.4 | R10: -50.7 | S10: -12.9
A11: {=Sheet5!A13:S19} -> #055 | B11: αβ | C11: 1618.177 | D11: 15.99 | E11: 0 | F11: 5 | G11: 50 | H11: 6.3333333 | I11: 4 | J11: 5.6666667 | K11: 7 | L11: 2 | M11: 2.5 | N11: 4.5462375 | O11: 4.337644 | P11: 6.429616 | Q11: -4.7 | R11: -4.7 | S11: 2.4
A12: #056 | B12: ααβ | C12: 1548.042 | D12: 18.66 | E12: 0 | F12: 5 | G12: 33.33 | H12: 4 | I12: 2.8 | J12: 3.6 | K12: 5.6 | L12: 2.2 | M12: 3.2 | N12: 5.6544286 | O12: 5.3974805 | P12: 4.5360529 | Q12: 44 | R12: -49.2 | S12: -21.6
A13: #057 | B13: ααβ | C13: 1590.123 | D13: 20.85 | E13: 0 | F13: 5 | G13: 33.33 | H13: 2.3333333 | I13: 2 | J13: 2.6666667 | K13: 4.3333333 | L13: 2 | M13: 3.6666667 | N13: 3.8842363 | O13: 4.1585675 | P13: 2.7655347 | Q13: 55.7 | R13: -46.4 | S13: -25.8
A14: #058 | B14: ααβ | C14: 1616.205 | D14: 22.1 | E14: 0 | F14: 5 | G14: 33.33 | H14: 2.3333333 | I14: 2.3333333 | J14: 2.3333333 | K14: 4 | L14: 3.6666667 | M14: 4.3333333 | N14: 2.7513564 | O14: 3.2700026 | P14: 0.76553475 | Q14: 76.1 | R14: -36.5 | S14: -27.7
A15: #059 | B15: αααβ | C15: 1534.015 | D15: 14.92 | E15: 0 | F15: 5 | G15: 25 | H15: 6 | I15: 5.6666667 | J15: 6 | K15: 7.6666667 | L15: 4.75 | M15: 3.6666667 | N15: 6.9634622 | O15: 6.4925371 | P15: 8.8920874 | Q15: 23.1 | R15: -48.9 | S15: -11.3
A16: #061 | B16: αβ | C16: 1644.259 | D16: 17.75 | E16: 0 | F16: 5 | G16: 50 | H16: 4 | I16: 4.3333333 | J16: 4.6666667 | K16: 6.6666667 | L16: 2.3333333 | M16: 4 | N16: 2.4423103 | O16: 2.7991045 | P16: 2.2016339 | Q16: -5 | R16: 1 | S16: 2.5
A17: #228 | B17: αααβ | C17: 1542.038 | D17: 18.92 | E17: 2 | F17: 5 | G17: 25 | H17: 3.3333333 | I17: 3.3333333 | J17: 3.6666667 | K17: 5.6666667 | L17: 2.6666667 | M17: 3.3333333 | N17: 3.7733258 | O17: 3.6490937 | P17: 2.9634741 | Q17: 80.5 | R17: -37.7 | S17: -30.3
A18: {=Sheet5!A25:S26} -> #024 | B18: αβαβααβ | C18: 1598.146 | D18: 18.12 | E18: 2 | F18: 5 | G18: 42.86 | H18: 4 | I18: 3 | J18: 4 | K18: 6 | L18: 2.3333333 | M18: 3 | N18: 4.1796605 | O18: 4.2231524 | P18: 6.2555007 | Q18: 18.8 | R18: -18 | S18: -10.6
A19: #049 | B19: αβαβααβ | C19: 1629.1473 | D19: 17.88 | E19: 0 | F19: 5 | G19: 42.86 | H19: 4 | I19: 3 | J19: 4.3333333 | K19: 6 | L19: 8 | M19: 5 | N19: 3.838814 | O19: 3.8762128 | P19: 5.0312187 | Q19: 5.7 | R19: 2.1 | S19: -2.9

Sheet Sheet5
B1: αβ_combination | C1: MW | D1: RT | E1: ACPC | F1: charge | G1: ab ratio | H1: MIC_CA | I1: MIC_CT | J1: MIC_CP | K1: MIC_CG | L1: MIC_SA | M1: MIC_EC | N1: IC50_HUVEC | O1: IC50_3T3 | P1: HC10 | Q1: Helicity | R1: ME100 | S1: ME15
A2: #001 | B2: α | C2: 1479.787 | D2: 22.89 | E2: 0 | F2: 1 | G2: 0 | H2: {=Sheet2!B2:I5} -> 6 | I2: 5.6666667 | J2: 6.6666667 | K2: 7.6666667 | L2: 5.6666667 | M2: 4.6666667 | N2: 6.0145556 | O2: 5.8101554 | P2: 5.129283 | Q2: 83.5 | R2: -23.4 | S2: -19.5
A3: #012 | B3: ααβ | C3: 1481.939 | D3: 16.28 | E3: 2 | F3: 5 | G3: 33.33 | H3: 4.6666667 | I3: 4 | J3: 4.6666667 | K3: 6.6666667 | L3: 3.6666667 | M3: 2.6666667 | N3: 6.9285302 | O3: 6.8948252 | P3: 7.7279205 | Q3: 55.7 | R3: -57.1 | S3: -31.8
A4: #013 | B4: ααβ | C4: 1524.02 | D4: 18.37 | E4: 2 | F4: 5 | G4: 33.33 | H4: 3 | I4: 2.6666667 | J4: 3.6666667 | K4: 5.6666667 | L4: 2 | M4: 2.3333333 | N4: 4.6641934 | O4: 4.6644793 | P4: 5.3680699 | Q4: 67.5 | R4: -58.8 | S4: -39.7
A5: #014 | B5: ααβ | C5: 1550.102 | D5: 19.45 | E5: 2 | F5: 5 | G5: 33.33 | H5: 2.3333333 | I5: 3 | J5: 3 | K5: 4.6666667 | L5: 2 | M5: 4.6666667 | N5: 2.9945497 | O5: 3.2390771 | P5: 1.8073549 | Q5: 88 | R5: -44.6 | S5: -39.3
A6: #029 | B6: ααβαααβ | C6: 1515.956 | D6: 17.18 | E6: 2 | F6: 5 | G6: 28.57 | H6: {=Sheet2!B7:I13} -> 4 | I6: 3.3333333 | J6: 3.6666667 | K6: 6 | L6: 3.3333333 | M6: 2.6666667 | N6: 6.5674964 | O6: 6.0126818 | P6: 7.243174 | Q6: 51.7 | R6: -53.7 | S6: -27.7
A7: #029-G1K-p6 | B7: ααβαααβ | C7: 1587.079 | D7: 15.13 | E7: 2 | F7: 6 | G7: 28.57 | H7: 4.6666667 | I7: 4 | J7: 4 | K7: 6.6666667 | L7: 3.3333333 | M7: 3 | N7: 6.9333809 | O7: 5.9820907 | P7: 7.8054214 | Q7: 46.9 | R7: -41.8 | S7: -19.6
A8: #032 | B8: ααβαααβ | C8: 1516.896 | D8: 19.17 | E8: 2 | F8: 3 | G8: 28.57 | H8: 5 | I8: 5 | J8: 5.3333333 | K8: 6.6666667 | L8: 4 | M8: 3 | N8: 6.6773725 | O8: 6.6707269 | P8: 7.1618877 | Q8: 70.7 | R8: -54.2 | S8: -38.3
A9: #035 | B9: ααβαααβ | C9: 1502.869 | D9: 19.67 | E9: 2 | F9: 3 | G9: 28.57 | H9: 4 | I9: 3.6666667 | J9: 4.3333333 | K9: 6.3333333 | L9: 3 | M9: 2.3333333 | N9: 5.7036429 | O9: 5.4373957 | P9: 5.5484366 | Q9: 73.1 | R9: -54.7 | S9: -40
A10: #038 | B10: ααβαααβ | C10: 1548.042 | D10: 16.97 | E10: 0 | F10: 5 | G10: 28.57 | H10: 4 | I10: 4.6666667 | J10: 4.6666667 | K10: 6.3333333 | L10: 2.5 | M10: 4 | N10: 5.6765852 | O10: 4.7248704 | P10: 5.9886847 | Q10: 25.4 | R10: -50.7 | S10: -12.9
A11: #052 | B11: αβαβααβ | C11: 1562.069 | D11: 13.72 | E11: 0 | F11: 5 | G11: 42.86 | H11: 8 | I11: 7.3333333 | J11: 7.3333333 | K11: 7.6666667 | L11: 8 | M11: 8 | N11: 8 | O11: 7 | P11: 8.7059779 | Q11: -1.5 | R11: 6.6 | S11: 0.8
A12: #053 | B12: αβαβααβ | C12: 1604.15 | D12: 15.2 | E12: 0 | F12: 5 | G12: 42.86 | H12: 7 | I12: 6 | J12: 7 | K12: 8 | L12: 8 | M12: 4 | N12: 6.1032552 | O12: 6.8783966 | P12: 8.9509932 | Q12: 0.3 | R12: 3.8 | S12: -0.1
A13: #055 | B13: αβ | C13: 1618.177 | D13: 15.99 | E13: 0 | F13: 5 | G13: 50 | H13: {=Sheet2!B15:I29} -> 6.3333333 | I13: 4 | J13: 5.6666667 | K13: 7 | L13: 2 | M13: 2.5 | N13: 4.5462375 | O13: 4.337644 | P13: 6.429616 | Q13: -4.7 | R13: -4.7 | S13: 2.4
A14: #056 | B14: ααβ | C14: 1548.042 | D14: 18.66 | E14: 0 | F14: 5 | G14: 33.33 | H14: 4 | I14: 2.8 | J14: 3.6 | K14: 5.6 | L14: 2.2 | M14: 3.2 | N14: 5.6544286 | O14: 5.3974805 | P14: 4.5360529 | Q14: 44 | R14: -49.2 | S14: -21.6
A15: #057 | B15: ααβ | C15: 1590.123 | D15: 20.85 | E15: 0 | F15: 5 | G15: 33.33 | H15: 2.3333333 | I15: 2 | J15: 2.6666667 | K15: 4.3333333 | L15: 2 | M15: 3.6666667 | N15: 3.8842363 | O15: 4.1585675 | P15: 2.7655347 | Q15: 55.7 | R15: -46.4 | S15: -25.8
A16: #058 | B16: ααβ | C16: 1616.205 | D16: 22.1 | E16: 0 | F16: 5 | G16: 33.33 | H16: 2.3333333 | I16: 2.3333333 | J16: 2.3333333 | K16: 4 | L16: 3.6666667 | M16: 4.3333333 | N16: 2.7513564 | O16: 3.2700026 | P16: 0.76553475 | Q16: 76.1 | R16: -36.5 | S16: -27.7
A17: #059 | B17: αααβ | C17: 1534.015 | D17: 14.92 | E17: 0 | F17: 5 | G17: 25 | H17: 6 | I17: 5.6666667 | J17: 6 | K17: 7.6666667 | L17: 4.75 | M17: 3.6666667 | N17: 6.9634622 | O17: 6.4925371 | P17: 8.8920874 | Q17: 23.1 | R17: -48.9 | S17: -11.3
A18: #061 | B18: αβ | C18: 1644.259 | D18: 17.75 | E18: 0 | F18: 5 | G18: 50 | H18: 4 | I18: 4.3333333 | J18: 4.6666667 | K18: 6.6666667 | L18: 2.3333333 | M18: 4 | N18: 2.4423103 | O18: 2.7991045 | P18: 2.2016339 | Q18: -5 | R18: 1 | S18: 2.5
A19: #228 | B19: αααβ | C19: 1542.038 | D19: 18.92 | E19: 2 | F19: 5 | G19: 25 | H19: 3.3333333 | I19: 3.3333333 | J19: 3.6666667 | K19: 5.6666667 | L19: 2.6666667 | M19: 3.3333333 | N19: 3.7733258 | O19: 3.6490937 | P19: 2.9634741 | Q19: 80.5 | R19: -37.7 | S19: -30.3
A20: #231 | B20: ααβ | C20: 1465.94 | D20: 13.95 | E20: 2 | F20: 5 | G20: 33.33 | H20: 6.3333333 | I20: 6.6666667 | J20: 6.3333333 | K20: 8 | L20: 5 | M20: 3.3333333 | N20: 8.8494486 | O20: 9.0111985 | P20: 9.5370175 | Q20: 57.1 | R20: -29.1 | S20: -16.6
A21: #239 | B21: ααβ | C21: 1481.939 | D21: 15.12 | E21: 2 | F21: 5 | G21: 33.33 | H21: 5.3333333 | I21: 5.3333333 | J21: 5.3333333 | K21: 7 | L21: 4 | M21: 3 | N21: 8.25719 | O21: 7.8981429 | P21: 9.159452 | Q21: 45.8 | R21: -43.6 | S21: -19.9
A22: #241 | B22: ααβ | C22: 1481.939 | D22: 14.45 | E22: 2 | F22: 5 | G22: 33.33 | H22: 6.3333333 | I22: 6.3333333 | J22: 6 | K22: 8 | L22: 4.3333333 | M22: 3.3333333 | N22: 8.2258879 | O22: 8.4711345 | P22: 10.591989 | Q22: 42.6 | R22: -43.5 | S22: -18.6
A23: #043 | B23: ααβαααβ | C23: 1599.1004 | D23: 23.26 | E23: 1 | F23: 5 | G23: 28.57 | H23: 2.6666667 | I23: 2.3333333 | J23: 2.6666667 | K23: 4 | L23: 2.6666667 | M23: 4.3333333 | N23: 1.8482565 | O23: 2.0507138 | P23: =LOG(1.4,2) -> 0.48542683 | Q23: 99 | R23: -48.7 | S23: -48.2
A24: #062 | B24: αααβ | C24: 1601.116 | D24: 21.67 | E24: 0 | F24: 5 | G24: 25 | H24: 2.6666667 | I24: 2.6666667 | J24: 3 | K24: 3.6666667 | L24: 3.3333333 | M24: 4.6666667 | N24: 1.8927217 | O24: 2.5432744 | P24: =LOG(1.4,2) -> 0.48542683 | Q24: 81.8 | R24: -51.5 | S24: -42.1
A25: #024 | B25: αβαβααβ | C25: 1598.146 | D25: 18.12 | E25: 2 | F25: 5 | G25: 42.86 | H25: 4 | I25: 3 | J25: 4 | K25: 6 | L25: 2.3333333 | M25: 3 | N25: 4.1796605 | O25: 4.2231524 | P25: =LOG(76.4,2) -> 6.2555007 | Q25: 18.8 | R25: -18 | S25: -10.6
A26: #049 | B26: αβαβααβ | C26: 1629.1473 | D26: 17.88 | E26: 0 | F26: 5 | G26: 42.86 | H26: 4 | I26: 3 | J26: 4.3333333 | K26: 6 | L26: 8 | M26: 5 | N26: 3.838814 | O26: 3.8762128 | P26: =LOG(32.7,2) -> 5.0312187 | Q26: 5.7 | R26: 2.1 | S26: -2.9
A27: #40 | B27: ααβαααβ | C27: 1616.205 | D27: 21.44 | E27: 0 | F27: 5 | G27: 28.57 | H27: 2.6666667 | I27: 2.6666667 | J27: 3.3333333 | K27: 4 | L27: 3.3333333 | M27: 4.3333333 | N27: 2.0984509 | O27: 2.1705677 | P27: =LOG(1.6,2) -> 0.67807191 | Q27: 79.8 | R27: -43.5 | S27: -34.7

Sheet Sheet5 (2)
B1: αβ_combination | C1: MW | D1: RT | E1: ACPC | F1: charge | G1: ab ratio | H1: MIC_CA | I1: MIC_CT | J1: MIC_CP | K1: MIC_CG | L1: MIC_SA | M1: MIC_EC | N1: IC50_HUVEC | O1: IC50_3T3 | P1: HC10 | Q1: Helicity | R1: ME100 | S1: ME15
A2: #001 | B2: α | C2: 1479.787 | D2: 22.89 | E2: 0 | F2: 1 | G2: 0 | H2: {=Sheet2!B2:I5} -> 6 | I2: 5.6666667 | J2: 6.6666667 | K2: 7.6666667 | L2: 5.6666667 | M2: 4.6666667 | N2: 6.0145556 | O2: 5.8101554 | P2: 5.129283 | Q2: 83.5 | R2: -23.4 | S2: -19.5 | T2: =2^P2 -> 35
A3: #012 | B3: ααβ | C3: 1481.939 | D3: 16.28 | E3: 2 | F3: 5 | G3: 33.33 | H3: 4.6666667 | I3: 4 | J3: 4.6666667 | K3: 6.6666667 | L3: 3.6666667 | M3: 2.6666667 | N3: 6.9285302 | O3: 6.8948252 | P3: 7.7279205 | Q3: 55.7 | R3: -57.1 | S3: -31.8 | T3: =2^P3 -> 212
A4: #013 | B4: ααβ | C4: 1524.02 | D4: 18.37 | E4: 2 | F4: 5 | G4: 33.33 | H4: 3 | I4: 2.6666667 | J4: 3.6666667 | K4: 5.6666667 | L4: 2 | M4: 2.3333333 | N4: 4.6641934 | O4: 4.6644793 | P4: 5.3680699 | Q4: 67.5 | R4: -58.8 | S4: -39.7 | T4: =2^P4 -> 41.3
A5: #014 | B5: ααβ | C5: 1550.102 | D5: 19.45 | E5: 2 | F5: 5 | G5: 33.33 | H5: 2.3333333 | I5: 3 | J5: 3 | K5: 4.6666667 | L5: 2 | M5: 4.6666667 | N5: 2.9945497 | O5: 3.2390771 | P5: 1.8073549 | Q5: 88 | R5: -44.6 | S5: -39.3 | T5: =2^P5 -> 3.5
A6: #029 | B6: ααβαααβ | C6: 1515.956 | D6: 17.18 | E6: 2 | F6: 5 | G6: 28.57 | H6: {=Sheet2!B7:I13} -> 4 | I6: 3.3333333 | J6: 3.6666667 | K6: 6 | L6: 3.3333333 | M6: 2.6666667 | N6: 6.5674964 | O6: 6.0126818 | P6: 7.243174 | Q6: 51.7 | R6: -53.7 | S6: -27.7 | T6: =2^P6 -> 151.5
A7: #029-G1K-p6 | B7: ααβαααβ | C7: 1587.079 | D7: 15.13 | E7: 2 | F7: 6 | G7: 28.57 | H7: 4.6666667 | I7: 4 | J7: 4 | K7: 6.6666667 | L7: 3.3333333 | M7: 3 | N7: 6.9333809 | O7: 5.9820907 | P7: 7.8054214 | Q7: 46.9 | R7: -41.8 | S7: -19.6 | T7: =2^P7 -> 223.7
A8: #032 | B8: ααβαααβ | C8: 1516.896 | D8: 19.17 | E8: 2 | F8: 3 | G8: 28.57 | H8: 5 | I8: 5 | J8: 5.3333333 | K8: 6.6666667 | L8: 4 | M8: 3 | N8: 6.6773725 | O8: 6.6707269 | P8: 7.1618877 | Q8: 70.7 | R8: -54.2 | S8: -38.3 | T8: =2^P8 -> 143.2
A9: #035 | B9: ααβαααβ | C9: 1502.869 | D9: 19.67 | E9: 2 | F9: 3 | G9: 28.57 | H9: 4 | I9: 3.6666667 | J9: 4.3333333 | K9: 6.3333333 | L9: 3 | M9: 2.3333333 | N9: 5.7036429 | O9: 5.4373957 | P9: 5.5484366 | Q9: 73.1 | R9: -54.7 | S9: -40 | T9: =2^P9 -> 46.8
A10: #038 | B10: ααβαααβ | C10: 1548.042 | D10: 16.97 | E10: 0 | F10: 5 | G10: 28.57 | H10: 4 | I10: 4.6666667 | J10: 4.6666667 | K10: 6.3333333 | L10: 2.5 | M10: 4 | N10: 5.6765852 | O10: 4.7248704 | P10: 5.9886847 | Q10: 25.4 | R10: -50.7 | S10: -12.9 | T10: =2^P10 -> 63.5
A11: #052 | B11: αβαβααβ | C11: 1562.069 | D11: 13.72 | E11: 0 | F11: 5 | G11: 42.86 | H11: 8 | I11: 7.3333333 | J11: 7.3333333 | K11: 7.6666667 | L11: 8 | M11: 8 | N11: 8 | O11: 7 | P11: 8.7059779 | Q11: -1.5 | R11: 6.6 | S11: 0.8 | T11: =2^P11 -> 417.6
A12: #053 | B12: αβαβααβ | C12: 1604.15 | D12: 15.2 | E12: 0 | F12: 5 | G12: 42.86 | H12: 7 | I12: 6 | J12: 7 | K12: 8 | L12: 8 | M12: 4 | N12: 6.1032552 | O12: 6.8783966 | P12: 8.9509932 | Q12: 0.3 | R12: 3.8 | S12: -0.1 | T12: =2^P12 -> 494.9
A13: #055 | B13: αβ | C13: 1618.177 | D13: 15.99 | E13: 0 | F13: 5 | G13: 50 | H13: {=Sheet2!B15:I24} -> 6.3333333 | I13: 4 | J13: 5.6666667 | K13: 7 | L13: 2 | M13: 2.5 | N13: 4.5462375 | O13: 4.337644 | P13: 6.429616 | Q13: -4.7 | R13: -4.7 | S13: 2.4 | T13: =2^P13 -> 86.2
A14: #056 | B14: ααβ | C14: 1548.042 | D14: 18.66 | E14: 0 | F14: 5 | G14: 33.33 | H14: 4 | I14: 2.8 | J14: 3.6 | K14: 5.6 | L14: 2.2 | M14: 3.2 | N14: 5.6544286 | O14: 5.3974805 | P14: 4.5360529 | Q14: 44 | R14: -49.2 | S14: -21.6 | T14: =2^P14 -> 23.2
A15: #057 | B15: ααβ | C15: 1590.123 | D15: 20.85 | E15: 0 | F15: 5 | G15: 33.33 | H15: 2.3333333 | I15: 2 | J15: 2.6666667 | K15: 4.3333333 | L15: 2 | M15: 3.6666667 | N15: 3.8842363 | O15: 4.1585675 | P15: 2.7655347 | Q15: 55.7 | R15: -46.4 | S15: -25.8 | T15: =2^P15 -> 6.8
A16: #058 | B16: ααβ | C16: 1616.205 | D16: 22.1 | E16: 0 | F16: 5 | G16: 33.33 | H16: 2.3333333 | I16: 2.3333333 | J16: 2.3333333 | K16: 4 | L16: 3.6666667 | M16: 4.3333333 | N16: 2.7513564 | O16: 3.2700026 | P16: 0.76553475 | Q16: 76.1 | R16: -36.5 | S16: -27.7 | T16: =2^P16 -> 1.7
A17: #059 | B17: αααβ | C17: 1534.015 | D17: 14.92 | E17: 0 | F17: 5 | G17: 25 | H17: 6 | I17: 5.6666667 | J17: 6 | K17: 7.6666667 | L17: 4.75 | M17: 3.6666667 | N17: 6.9634622 | O17: 6.4925371 | P17: 8.8920874 | Q17: 23.1 | R17: -48.9 | S17: -11.3 | T17: =2^P17 -> 475.1
A18: #061 | B18: αβ | C18: 1644.259 | D18: 17.75 | E18: 0 | F18: 5 | G18: 50 | H18: 4 | I18: 4.3333333 | J18: 4.6666667 | K18: 6.6666667 | L18: 2.3333333 | M18: 4 | N18: 2.4423103 | O18: 2.7991045 | P18: 2.2016339 | Q18: -5 | R18: 1 | S18: 2.5 | T18: =2^P18 -> 4.6
A19: #228 | B19: αααβ | C19: 1542.038 | D19: 18.92 | E19: 2 | F19: 5 | G19: 25 | H19: 3.3333333 | I19: 3.3333333 | J19: 3.6666667 | K19: 5.6666667 | L19: 2.6666667 | M19: 3.3333333 | N19: 3.7733258 | O19: 3.6490937 | P19: 2.9634741 | Q19: 80.5 | R19: -37.7 | S19: -30.3 | T19: =2^P19 -> 7.8
A20: #231 | B20: ααβ-wc | C20: 1465.94 | D20: 13.95 | E20: 2 | F20: 5 | G20: 33.33 | H20: 6.3333333 | I20: 6.6666667 | J20: 6.3333333 | K20: 8 | L20: 5 | M20: 3.3333333 | N20: 8.8494486 | O20: 9.0111985 | P20: 10.280771 | Q20: 57.1 | R20: -29.1 | S20: -16.6 | T20: =2^P20 -> 1244
A21: #239 | B21: ααβ-wc | C21: 1481.939 | D21: 15.12 | E21: 2 | F21: 5 | G21: 33.33 | H21: 5.3333333 | I21: 5.3333333 | J21: 5.3333333 | K21: 7 | L21: 4 | M21: 3 | N21: 8.25719 | O21: 7.8981429 | P21: 9.4458426 | Q21: 45.8 | R21: -43.6 | S21: -19.9 | T21: =2^P21 -> 697.4
A22: #241 | B22: ααβ-wc | C22: 1481.939 | D22: 14.45 | E22: 2 | F22: 5 | G22: 33.33 | H22: 6.3333333 | I22: 6.3333333 | J22: 6 | K22: 8 | L22: 4.3333333 | M22: 3.3333333 | N22: 8.2258879 | O22: 8.4711345 | P22: 10.483514 | Q22: 42.6 | R22: -43.5 | S22: -18.6 | T22: =2^P22 -> 1431.7
S26: predicted | V26: actual
H27: =2^($P20-H20) -> 15.427554 | I27: =2^($P20-I20) -> 12.244858 | J27: =2^($P20-J20) -> 15.427554 | K27: =2^($P20-K20) -> 4.859375 | L27: =2^($P20-L20) -> 38.875 | M27: =2^($P20-M20) -> 123.42043 | N27: =2^($P20-N20) -> 2.6969377 | O27: =2^($P20-O20) -> 2.4109007 | P27: =2^($P20-P20) -> 1 | S27: 8.32 | T27: 7.5 | V27: 8.8917837 | W27: 8.5507468
B28: 1.4 | C28: =2^B28 -> 2.6390158 | H28: =2^($P21-H21) -> 17.297711 | I28: =2^($P21-I21) -> 17.297711 | J28: =2^($P21-J21) -> 17.297711 | K28: =2^($P21-K21) -> 5.4484375 | L28: =2^($P21-L21) -> 43.5875 | M28: =2^($P21-M21) -> 87.175 | N28: =2^($P21-N21) -> 2.2793975 | O28: =2^($P21-O21) -> 2.9235062 | P28: =2^($P21-P21) -> 1 | S28: 7.73 | T28: 7.04 | V28: 8.6073303 | W28: 7.6438562
B29: 1.4 | C29: =2^B29 -> 2.6390158 | H29: =2^($P22-H22) -> 17.755329 | I29: =2^($P22-I22) -> 17.755329 | J29: =2^($P22-J22) -> 22.370313 | K29: =2^($P22-K22) -> 5.5925781 | L29: =2^($P22-L22) -> 71.021315 | M29: =2^($P22-M22) -> 142.04263 | N29: =2^($P22-N22) -> 4.782038 | O29: =2^($P22-O22) -> 4.0344696 | P29: =2^($P22-P22) -> 1 | S29: 8.03 | T29: 7.26 | V29: 8.8137812 | W29: 8.6073303
B30: =LOG(76.4,2) -> 6.2555007 | C30: =2^B30 -> 76.4
B31: =LOG(32.7,2) -> 5.0312187 | C31: =2^B31 -> 32.7 | H31: =2^($P6-H6) -> 9.46875 | I31: =2^($P6-I6) -> 15.030704 | J31: =2^($P6-J6) -> 11.929877 | K31: =2^($P6-K6) -> 2.3671875 | L31: =2^($P6-L6) -> 15.030704 | M31: =2^($P6-M6) -> 23.859755 | N31: =2^($P6-N6) -> 1.5973468 | O31: =2^($P6-O6) -> 2.3464702 | P31: =2^($P6-P6) -> 1
S32: error
H33: =H27/H$31 -> 1.6293126 | I33: =I27/I$31 -> 0.81465632 | J33: =J27/J$31 -> 1.2931863 | K33: =K27/K$31 -> 2.0528053 | L33: =L27/L$31 -> 2.5863726 | M33: =M27/M$31 -> 5.1727452 | N33: =N27/N$31 -> 1.6883858 | O33: =O27/O$31 -> 1.0274585 | P33: =P27/P$31 -> 1 | S33: =ABS(S27-V27) -> 0.5717837 | T33: =ABS(T27-W27) -> 1.0507468
H34: =H28/H$31 -> 1.8268209 | I34: =I28/I$31 -> 1.1508251 | J34: =J28/J$31 -> 1.4499487 | K34: =K28/K$31 -> 2.3016502 | L34: =L28/L$31 -> 2.8998975 | M34: =M28/M$31 -> 3.6536419 | N34: =N28/N$31 -> 1.4269897 | O34: =O28/O$31 -> 1.2459166 | P34: =P28/P$31 -> 1 | S34: =ABS(S28-V28) -> 0.87733031 | T34: =ABS(T28-W28) -> 0.60385619
H35: =H29/H$31 -> 1.8751502 | I35: =I29/I$31 -> 1.1812706 | J35: =J29/J$31 -> 1.8751502 | K35: =K29/K$31 -> 2.3625413 | L35: =L29/L$31 -> 4.7250825 | M35: =M29/M$31 -> 5.9532309 | N35: =N29/N$31 -> 2.9937381 | O35: =O29/O$31 -> 1.7193781 | P35: =P29/P$31 -> 1 | S35: =ABS(S29-V29) -> 0.78378119 | T35: =ABS(T29-W29) -> 1.3473303
H37: =AVERAGE(H20:M20) -> 5.9444444 | I37: =AVERAGE(N20:P20) -> 9.3804726 | J37: =I37-H37 -> 3.4360282 | M37: 3.21272
H38: =AVERAGE(H21:M21) -> 5 | I38: =AVERAGE(N21:P21) -> 8.5337252 | J38: =I38-H38 -> 3.5337252 | M38: 3.01049
H39: =AVERAGE(H22:M22) -> 5.7222222 | I39: =AVERAGE(N22:P22) -> 9.0601786 | J39: =I39-H39 -> 3.3379564 | M39: 3.2084
I40: Peptide Number | J40: Actual Broad Spectrum Selectivity | K40: Predicted Selectivity
I41: 231 | J41: =2^J37 -> 10.822997 | K41: =2^M37 -> 9.2709681
I42: 239 | J42: =2^J38 -> 11.581299 | K42: =2^M38 -> 8.0583809
I43: 241 | J43: =2^J39 -> 10.111719 | K43: =2^M39 -> 9.2432487
G44: Peptide Number | H44: C. albicans | I44: C. tropicalis | J44: C. parapsilosis | K44: C. glabrata | L44: S. aureus | M44: E. coli
...

Sheet Sheet2
B1: CA_MIC | C1: CT | D1: CP | E1: CG | F1: SA | G1: EC | H1: HUVEC_IC50 | I1: 3T3_IC50 | L1: HC10 (MyungRyul) | O1: CA_MIC | P1: CT | Q1: CP | R1: CG | S1: SA | T1: EC | U1: HUVEC_IC50 | V1: 3T3_IC50
A2: #001 | B2: {=LOG(O2:V29,2)} -> 6 | C2: 5.6666667 | D2: 6.6666667 | E2: 7.6666667 | F2: 5.6666667 | G2: 4.6666667 | H2: 6.0145556 | I2: 5.8101554 | O2: {='[1]Final Compiled data (geomean)'!$D$2:$K$29} -> 64 | P2: 50.796834 | Q2: 101.59367 | R2: 203.18733 | S2: 50.796834 | T2: 25.398417 | U2: 64.648973 | V2: 56.108809
A3: #012 | B3: 4.6666667 | C3: 4 | D3: 4.6666667 | E3: 6.6666667 | F3: 3.6666667 | G3: 2.6666667 | H3: 6.9285302 | I3: 6.8948252 | O3: 25.398417 | P3: 16 | Q3: 25.398417 | R3: 101.59367 | S3: 12.699208 | T3: 6.3496042 | U3: 121.8135 | V3: 119.00061
A4: #013 | B4: 3 | C4: 2.6666667 | D4: 3.6666667 | E4: 5.6666667 | F4: 2 | G4: 2.3333333 | H4: 4.6641934 | I4: 4.6644793 | O4: 8 | P4: 6.3496042 | Q4: 12.699208 | R4: 50.796834 | S4: 4 | T4: 5.0396842 | U4: 25.354913 | V4: 25.359938
A5: #014 | B5: 2.3333333 | C5: 3 | D5: 3 | E5: 4.6666667 | F5: 2 | G5: 4.6666667 | H5: 2.9945497 | I5: 3.2390771 | O5: 5.0396842 | P5: 8 | Q5: 8 | R5: 25.398417 | S5: 4 | T5: 25.398417 | U5: 7.9698343 | V5: 9.4418994
A6: #026 | B6: 6 | C6: 6 | D6: 8 | E6: 8 | F6: 7 | G6: 6 | H6: 6.6546753 | I6: 6.7325576 | O6: 64 | P6: 64 | Q6: 256 | R6: 256 | S6: 128 | T6: 64 | U6: 100.75275 | V6: 106.34125
A7: #029 | B7: 4 | C7: 3.3333333 | D7: 3.6666667 | E7: 6 | F7: 3.3333333 | G7: 2.6666667 | H7: 6.5674964 | I7: 6.0126818 | O7: 16 | P7: 10.079368 | Q7: 12.699208 | R7: 64 | S7: 10.079368 | T7: 6.3496042 | U7: 94.844775 | V7: 64.565064
A8: #029-G1K-p6 | B8: 4.6666667 | C8: 4 | D8: 4 | E8: 6.6666667 | F8: 3.3333333 | G8: 3 | H8: 6.9333809 | I8: 5.9820907 | O8: 25.398417 | P8: 16 | Q8: 16 | R8: 101.59367 | S8: 10.079368 | T8: 8 | U8: 122.22376 | V8: 63.21043
A9: #032 | B9: 5 | C9: 5 | D9: 5.3333333 | E9: 6.6666667 | F9: 4 | G9: 3 | H9: 6.6773725 | I9: 6.6707269 | O9: 32 | P9: 32 | Q9: 40.317474 | R9: 101.59367 | S9: 16 | T9: 8 | U9: 102.35037 | V9: 101.87999
A10: #035 | B10: 4 | C10: 3.6666667 | D10: 4.3333333 | E10: 6.3333333 | F10: 3 | G10: 2.3333333 | H10: 5.7036429 | I10: 5.4373957 | O10: 16 | P10: 12.699208 | Q10: 20.158737 | R10: 80.634947 | S10: 8 | T10: 5.0396842 | U10: 52.115584 | V10: 43.333044
A11: #038 | B11: 4 | C11: 4.6666667 | D11: 4.6666667 | E11: 6.3333333 | F11: 2.5 | G11: 4 | H11: 5.6765852 | I11: 4.7248704 | O11: 16 | P11: 25.398417 | Q11: 25.398417 | R11: 80.634947 | S11: 5.6568542 | T11: 16 | U11: 51.147264 | V11: 26.444034
A12: #052 | B12: 8 | C12: 7.3333333 | D12: 7.3333333 | E12: 7.6666667 | F12: 8 | G12: 8 | H12: 8 | I12: 7 | O12: 256 | P12: 161.26989 | Q12: 161.26989 | R12: 203.18733 | S12: 256 | T12: 256 | U12: 256 | V12: 128
A13: #053 | B13: 7 | C13: 6 | D13: 7 | E13: 8 | F13: 8 | G13: 4 | H13: 6.1032552 | I13: 6.8783966 | O13: 128 | P13: 64 | Q13: 128 | R13: 256 | S13: 256 | T13: 16 | U13: 68.748448 | V13: 117.65319
A14: #054 | B14: 8 | C14: 8 | D14: 8 | E14: 8 | F14: 7.3333333 | G14: 6.3333333 | H14: 6.9366486 | I14: 7 | O14: 256 | P14: 256 | Q14: 256 | R14: 256 | S14: 161.26989 | T14: 80.634947 | U14: 122.5009 | V14: 128
... A29: #40 | B29: 2.6666667 | C29: 2.6666667 | D29: 3.3333333 | E29: 4 | F29: 3.3333333 | G29: 4.3333333 | H29: 2.0984509 | I29: 2.1705677 | O29: 6.3496042 | P29: 6.3496042 | Q29: 10.079368 | R29: 16 | S29: 10.079368 | T29: 20.158737 | U29: 4.2824931 | V29: 4.5020051
